<?xml version="1.0" encoding="utf-8"?>
<!-- This URDF was automatically created by SolidWorks to URDF Exporter! Originally created by Stephen Brawner (brawner@gmail.com) 
     Commit Version: 1.6.0-4-g7f85cfe  Build Version: 1.6.7995.38578
     For more information, please see http://wiki.ros.org/sw_urdf_exporter -->
<robot
  name="atom01urdf">
  <link
    name="base_link">
    <inertial>
      <origin
        xyz="-0.04874715 -0.00009475  -0.01134147"
        rpy="0 0 0" />
      <mass
        value="5.38006123" />
      <inertia
        ixx="0.02803526"
        ixy="-0.00002867"
        ixz="-0.00453235"
        iyy="0.02606074"
        iyz="-0.00000804"
        izz="0.03774568" />
    </inertial>
    <visual>
      <origin
        xyz="0 0 0"
        rpy="0 0 0" />
      <geometry>
        <mesh
          filename="../meshes/base_link.STL" />
      </geometry>
      <material
        name="">
        <color
          rgba="0.898039215686275 0.917647058823529 0.929411764705882 1" />
      </material>
    </visual>
    <collision>
      <origin
        xyz="0 0 0"
        rpy="0 0 0" />
      <geometry>
        <mesh
          filename="../meshes/base_link.STL" />
      </geometry>
    </collision>
  </link>
  <link
    name="left_thigh_yaw_link">
    <inertial>
      <origin
        xyz="-0.03475324 -0.00011232  -0.05728887"
        rpy="0 0 0" />
      <mass
        value="1.70245957" />
      <inertia
        ixx=" 0.00732126"
        ixy="-0.000008"
        ixz="-0.00382108"
        iyy="0.00903647"
        iyz="-0.00001157"
        izz="0.00330863" />
    </inertial>
    <visual>
      <origin
        xyz="0 0 0"
        rpy="0 0 0" />
      <geometry>
        <mesh
          filename="../meshes/left_thigh_yaw_link.STL" />
      </geometry>
      <material
        name="">
        <color
          rgba="0.898039215686275 0.917647058823529 0.929411764705882 1" />
      </material>
    </visual>
    <!-- <collision>
      <origin
        xyz="0 0 0"
        rpy="0 0 0" />
      <geometry>
        <mesh
          filename="../meshes/left_thigh_yaw_link.STL" />
      </geometry>
    </collision> -->
  </link>
  <joint
    name="left_thigh_yaw_joint"
    type="revolute">
    <origin
      xyz="-0.071093 0.0725 -0.051778"
      rpy="0 0 0" />
    <parent
      link="base_link" />
    <child
      link="left_thigh_yaw_link" />
    <axis
      xyz="0.5 0 0.86603" />
    <limit
      lower="-0.2"
      upper="1"
      effort="80"
      velocity="10.47" />
  </joint>
  <link
    name="left_thigh_roll_link">
    <inertial>
      <origin
        xyz=" 0.05562209 -0.00172039 -0.03184052"
        rpy="0 0 0" />
      <mass
        value="1.71072574" />
      <inertia
        ixx="0.00287342"
        ixy="-0.00017789"
        ixz="-0.00324267"
        iyy=" 0.00911186"
        iyz="-0.00010778"
        izz="0.00669399" />
    </inertial>
    <visual>
      <origin
        xyz="0 0 0"
        rpy="0 0 0" />
      <geometry>
        <mesh
          filename="../meshes/left_thigh_roll_link.STL" />
      </geometry>
      <material
        name="">
        <color
          rgba="0.752941176470588 0.752941176470588 0.752941176470588 1" />
      </material>
    </visual>
    <!-- <collision>
      <origin
        xyz="0 0 0"
        rpy="0 0 0" />
      <geometry>
        <mesh
          filename="../meshes/left_thigh_roll_link.STL" />
      </geometry>
    </collision> -->
  </link>
  <joint
    name="left_thigh_roll_joint"
    type="revolute">
    <origin
      xyz="-0.017693 0 -0.072346"
      rpy="0 0 0" />
    <parent
      link="left_thigh_yaw_link" />
    <child
      link="left_thigh_roll_link" />
    <axis
      xyz="0.86603 0 -0.5" />
    <limit
      lower="-0.2"
      upper="1"
      effort="80"
      velocity="10.47" />
  </joint>
  <link
    name="left_thigh_pitch_link">
    <inertial>
      <origin
        xyz=" 0.00015459  -0.01594857 -0.19845479"
        rpy="0 0 0" />
      <mass
        value="2.34679679" />
      <inertia
        ixx="0.1119784"
        ixy="-0.00000275"
        ixz="-0.00010501"
        iyy="0.11231318"
        iyz="-0.00920814"
        izz="0.0024318" />
    </inertial>
    <visual>
      <origin
        xyz="0 0 0"
        rpy="0 0 0" />
      <geometry>
        <mesh
          filename="../meshes/left_thigh_pitch_link.STL" />
      </geometry>
      <material
        name="">
        <color
          rgba="0.898039215686275 0.917647058823529 0.929411764705882 1" />
      </material>
    </visual>
    <!-- <collision>
      <origin
        xyz="0 0 0"
        rpy="0 0 0" />
      <geometry>
        <mesh
          filename="../meshes/left_thigh_pitch_link.STL" />
      </geometry>
    </collision> -->
    <collision>
      <origin
        xyz="0.0 0 -0.08"
        rpy="0 0 0" />
      <geometry>
        <box name="left_thigh_pitch_link" size="0.08 0.1 0.22"/>
      </geometry>
    </collision>
  </link>
  <joint
    name="left_thigh_pitch_joint"
    type="revolute">
    <origin
      xyz="0.060622 0.02085 -0.035"
      rpy="0 0 0" />
    <parent
      link="left_thigh_roll_link" />
    <child
      link="left_thigh_pitch_link" />
    <axis
      xyz="0 1 0" />
    <limit
      lower="-1"
      upper="1"
      effort="80"
      velocity="10.47" />
  </joint>
  <link
    name="left_knee_link">
    <inertial>
      <origin
        xyz=" -0.00032236  -0.01193193  -0.14554011"
        rpy="0 0 0" />
      <mass
        value="1.79036871 " />
      <inertia
        ixx="0.05038999"
        ixy="-0.00001321"
        ixz="-0.00005627"
        iyy="0.04987102"
        iyz="-0.00346432"
        izz="0.00146349" />
    </inertial>
    <visual>
      <origin
        xyz="0 0 0"
        rpy="0 0 0" />
      <geometry>
        <mesh
          filename="../meshes/left_knee_link.STL" />
      </geometry>
      <material
        name="">
        <color
          rgba="0.898039215686275 0.917647058823529 0.929411764705882 1" />
      </material>
    </visual>
    <!-- <collision>
      <origin
        xyz="0 0 0"
        rpy="0 0 0" />
      <geometry>
        <mesh
          filename="../meshes/left_knee_link.STL" />
      </geometry>
    </collision> -->
    <collision>
      <origin
        xyz="0.0 0 -0.15"
        rpy="0 0 0" />
      <geometry>
        <box name="right_knee_link" size="0.08 0.08 0.22"/>
      </geometry>
    </collision>
  </link>
  <joint
    name="left_knee_joint"
    type="revolute">
    <origin
      xyz="0 0 -0.25"
      rpy="0 0 0" />
    <parent
      link="left_thigh_pitch_link" />
    <child
      link="left_knee_link" />
    <axis
      xyz="0 1 0" />
    <limit
      lower="-1.5"
      upper="1.5"
      effort="80"
      velocity="10.47" />
  </joint>
  <link
    name="left_ankle_pitch_link">
    <inertial>
      <origin
        xyz="0 0 0"
        rpy="0 0 0" />
      <mass
        value="0.084" />
      <inertia
        ixx="0.00000863"
        ixy="0"
        ixz="0"
        iyy="0.00000863"
        iyz="0"
        izz="0.00001448" />
    </inertial>
    <visual>
      <origin
        xyz="0 0 0"
        rpy="0 0 0" />
      <geometry>
        <mesh
          filename="../meshes/left_ankle_pitch_link.STL" />
      </geometry>
      <material
        name="">
        <color
          rgba="1 1 1 1" />
      </material>
    </visual>
    <!-- <collision>
      <origin
        xyz="0 0 0"
        rpy="0 0 0" />
      <geometry>
        <mesh
          filename="../meshes/left_ankle_pitch_link.STL" />
      </geometry>
    </collision> -->
  </link>
  <joint
    name="left_ankle_pitch_joint"
    type="revolute">
    <origin
      xyz="0 -0.02085 -0.3"
      rpy="0 0 0" />
    <parent
      link="left_knee_link" />
    <child
      link="left_ankle_pitch_link" />
    <axis
      xyz="0 1 0" />
    <limit
      lower="-1.5"
      upper="1.3"
      effort="18"
      velocity="3.7692" />
  </joint>
  <link
    name="left_ankle_roll_link">
    <inertial>
      <origin
        xyz="0.01521399 0.00220247 -0.02960539"
        rpy="0 0 0" />
      <mass
        value="0.32034036 " />
      <inertia
        ixx=" 0.000402"
        ixy="0"
        ixz="0.00017084"
        iyy="0.00089244"
        iyz="-0.00000894"
        izz="0.0006553" />
    </inertial>
    <visual>
      <origin
        xyz="0 0 0"
        rpy="0 0 0" />
      <geometry>
        <mesh
          filename="../meshes/left_ankle_roll_link.STL" />
      </geometry>
      <material
        name="">
        <color
          rgba="0.898039215686275 0.917647058823529 0.929411764705882 1" />
      </material>
    </visual>
    <collision>
      <origin
        xyz="0 0 0"
        rpy="0 0 0" />
      <geometry>
        <mesh
          filename="../meshes/left_ankle_roll_link.STL" />
      </geometry>
    </collision>
  </link>
  <joint
    name="left_ankle_roll_joint"
    type="revolute">
    <origin
      xyz="0 0 0"
      rpy="0 0 0" />
    <parent
      link="left_ankle_pitch_link" />
    <child
      link="left_ankle_roll_link" />
    <axis
      xyz="1 0 0" />
    <limit
      lower="-0.5"
      upper="0.5"
      effort="18"
      velocity="3.7692" />
  </joint>
  <link
    name="right_thigh_yaw_link">
    <inertial>
      <origin
        xyz="-0.03484738  -0.00011554  -0.05711815"
        rpy="0 0 0" />
      <mass
        value="1.68565743"/>
      <inertia
        ixx="0.007179"
        ixy="-0.00000736"
        ixz="-0.00378571"
        iyy="0.00890804"
        iyz="-0.00001262"
        izz="0.00327044" />
    </inertial>
    <visual>
      <origin
        xyz="0 0 0"
        rpy="0 0 0" />
      <geometry>
        <mesh
          filename="../meshes/right_thigh_yaw_link.STL" />
      </geometry>
      <material
        name="">
        <color
          rgba="0.898039215686275 0.917647058823529 0.929411764705882 1" />
      </material>
    </visual>
    <!-- <collision>
      <origin
        xyz="0 0 0"
        rpy="0 0 0" />
      <geometry>
        <mesh
          filename="../meshes/right_thigh_yaw_link.STL" />
      </geometry>
    </collision> -->
  </link>
  <joint
    name="right_thigh_yaw_joint"
    type="revolute">
    <origin
      xyz="-0.071093 -0.0725 -0.051778"
      rpy="0 0 0" />
    <parent
      link="base_link" />
    <child
      link="right_thigh_yaw_link" />
    <axis
      xyz="0.5 0 0.86603" />
    <limit
      lower="-1"
      upper="0.2"
      effort="80"
      velocity="10.47" />
  </joint>
  <link
    name="right_thigh_roll_link">
    <inertial>
      <origin
        xyz="0.05680729 0.00172039 -0.0327877"
        rpy="0 0 0" />
      <mass
        value="1.71072574" />
      <inertia
        ixx="0.00298139"
        ixy="-0.00018165"
        ixz="-0.00340107"
        iyy="0.00944463"
        iyz="-0.00011011"
        izz="0.00691879" />
    </inertial>
    <visual>
      <origin
        xyz="0 0 0"
        rpy="0 0 0" />
      <geometry>
        <mesh
          filename="../meshes/right_thigh_roll_link.STL" />
      </geometry>
      <material
        name="">
        <color
          rgba="0.898039215686275 0.917647058823529 0.929411764705882 1" />
      </material>
    </visual>
    <!-- <collision>
      <origin
        xyz="0 0 0"
        rpy="0 0 0" />
      <geometry>
        <mesh
          filename="../meshes/right_thigh_roll_link.STL" />
      </geometry>
    </collision> -->
  </link>
  <joint
    name="right_thigh_roll_joint"
    type="revolute">
    <origin
      xyz="-0.0189924084475403 0 -0.0715958163677252"
      rpy="0 0 0" />
    <parent
      link="right_thigh_yaw_link" />
    <child
      link="right_thigh_roll_link" />
    <axis
      xyz="0.866025403709318 0 -0.500000000130112" />
    <limit
      lower="-1"
      upper="0.2"
      effort="80"
      velocity="10.47" />
  </joint>
  <link
    name="right_thigh_pitch_link">
    <inertial>
      <origin
        xyz="-0.00001184 0.01594857  -0.19845479"
        rpy="0 0 0" />
      <mass
        value="2.34679679" />
      <inertia
        ixx="0.1119784"
        ixy="-0.00000554"
        ixz="-0.00000606"
        iyy="0.11231318"
        iyz="-0.00920814"
        izz="0.0024318" />
    </inertial>
    <visual>
      <origin
        xyz="0 0 0"
        rpy="0 0 0" />
      <geometry>
        <mesh
          filename="../meshes/right_thigh_pitch_link.STL" />
      </geometry>
      <material
        name="">
        <color
          rgba="0.898039215686275 0.917647058823529 0.929411764705882 1" />
      </material>
    </visual>
    <!-- <collision>
      <origin
        xyz="0 0 0"
        rpy="0 0 0" />
      <geometry>
        <mesh
          filename="../meshes/right_thigh_pitch_link.STL" />
      </geometry>
    </collision> -->
     <collision>
      <origin
        xyz="0.0 0 -0.08"
        rpy="0 0 0" />
      <geometry>
        <box name="right_thigh_pitch_link" size="0.08 0.1 0.22"/>
      </geometry>
    </collision>
  </link>
  <joint
    name="right_thigh_pitch_joint"
    type="revolute">
    <origin
      xyz="0.0619208163652291 -0.0208499999999942 -0.0357500000093095"
      rpy="0 0 0" />
    <parent
      link="right_thigh_roll_link" />
    <child
      link="right_thigh_pitch_link" />
    <axis
      xyz="0 1 0" />
    <limit
      lower="-1"
      upper="1"
      effort="80"
      velocity="10.47" />
  </joint>
  <link
    name="right_knee_link">
    <inertial>
      <origin
        xyz="0.00034876 0.01193193 -0.14550316"
        rpy="0 0 0" />
      <mass
        value="1.79036871" />
      <inertia
        ixx="0.05036948"
        ixy="-0.00001321"
        ixz="-0.00006359"
        iyy="0.04985051"
        iyz="-0.00346431"
        izz="0.00146349" />
    </inertial>
    <visual>
      <origin
        xyz="0 0 0"
        rpy="0 0 0" />
      <geometry>
        <mesh
          filename="../meshes/right_knee_link.STL" />
      </geometry>
      <material
        name="">
        <color
          rgba="0.898039215686275 0.917647058823529 0.929411764705882 1" />
      </material>
    </visual>
    <!-- <collision>
      <origin
        xyz="0 0 0"
        rpy="0 0 0" />
      <geometry>
        <mesh
          filename="../meshes/right_knee_link.STL" />
      </geometry>
    </collision> -->
    <collision>
      <origin
        xyz="0.0 0 -0.15"
        rpy="0 0 0" />
      <geometry>
        <box name="right_knee_link" size="0.08 0.08 0.22"/>
      </geometry>
    </collision>
  </link>
  <joint
    name="right_knee_joint"
    type="revolute">
    <origin
      xyz="0 0 -0.250000000000016"
      rpy="0 0 0" />
    <parent
      link="right_thigh_pitch_link" />
    <child
      link="right_knee_link" />
    <axis
      xyz="0 1 0" />
    <limit
      lower="-1.5"
      upper="1.5"
      effort="80"
      velocity="10.47" />
  </joint>
  <link
    name="right_ankle_pitch_link">
    <inertial>
      <origin
        xyz="0 0 0"
        rpy="0 0 0" />
      <mass
        value="0.084" />
      <inertia
        ixx="0.00000863"
        ixy="0"
        ixz="0"
        iyy="0.00000863"
        iyz="0"
        izz="0.00001448" />
    </inertial>
    <visual>
      <origin
        xyz="0 0 0"
        rpy="0 0 0" />
      <geometry>
        <mesh
          filename="../meshes/right_ankle_pitch_link.STL" />
      </geometry>
      <material
        name="">
        <color
          rgba="1 1 1 1" />
      </material>
    </visual>
    <!-- <collision>
      <origin
        xyz="0 0 0"
        rpy="0 0 0" />
      <geometry>
        <mesh
          filename="../meshes/right_ankle_pitch_link.STL" />
      </geometry>
    </collision> -->
  </link>
  <joint
    name="right_ankle_pitch_joint"
    type="revolute">
    <origin
      xyz="0 0.0208500000000073 -0.299999999999986"
      rpy="0 0 0" />
    <parent
      link="right_knee_link" />
    <child
      link="right_ankle_pitch_link" />
    <axis
      xyz="0 1 0" />
    <limit
      lower="-1.5"
      upper="1.3"
      effort="18"
      velocity="3.7692" />
  </joint>
  <link
    name="right_ankle_roll_link">
    <inertial>
      <origin
        xyz="0.01521399 -0.00220269 -0.02960539"
        rpy="0 0 0" />
      <mass
        value="0.32034036" />
      <inertia
        ixx="0.000402"
        ixy="0"
        ixz="-0.00017084"
        iyy="0.00089244"
        iyz="-0.00000894"
        izz="0.0006553" />
    </inertial>
    <visual>
      <origin
        xyz="0 0 0"
        rpy="0 0 0" />
      <geometry>
        <mesh
          filename="../meshes/right_ankle_roll_link.STL" />
      </geometry>
      <material
        name="">
        <color
          rgba="0.898039215686275 0.917647058823529 0.929411764705882 1" />
      </material>
    </visual>
    <collision>
      <origin
        xyz="0 0 0"
        rpy="0 0 0" />
      <geometry>
        <mesh
          filename="../meshes/right_ankle_roll_link.STL" />
      </geometry>
    </collision>
  </link>
  <joint
    name="right_ankle_roll_joint"
    type="revolute">
    <origin
      xyz="0 0 0"
      rpy="0 0 0" />
    <parent
      link="right_ankle_pitch_link" />
    <child
      link="right_ankle_roll_link" />
    <axis
      xyz="1 0 0" />
    <limit
      lower="-0.5"
      upper="0.5"
      effort="18"
      velocity="3.7692" />
  </joint>
  <link
    name="torso_link">
    <inertial>
      <origin
        xyz="-0.00231194 -0.0000924 0.09619627"
        rpy="0 0 0" />
      <mass
        value="7.65615208" />
      <inertia
        ixx="0.14149669"
        ixy="-0.00004306"
        ixz="-0.0039639"
        iyy="0.12890218"
        iyz="-0.000118"
        izz="0.03983686" />
    </inertial>
    <visual>
      <origin
        xyz="0 0 0"
        rpy="0 0 0" />
      <geometry>
        <mesh
          filename="../meshes/torso_link.STL" />
      </geometry>
      <material
        name="">
        <color
          rgba="1 1 1 1" />
      </material>
    </visual>
    <collision>
      <origin
        xyz="0 0 0.15"
        rpy="0 0 0" />
      <geometry>
        <box name="torso_link" size="0.16 0.16 0.22"/>
      </geometry>
    </collision>
  </link>
  <joint
    name="torso_joint"
    type="revolute">
    <origin
      xyz="-0.0281649492242451 0 0.0672000000054882"
      rpy="0 0 0" />
    <parent
      link="base_link" />
    <child
      link="torso_link" />
    <axis
      xyz="0 0 1" />
    <limit
      lower="-3.14"
      upper="3.14"
      effort="80"
      velocity="10.47" />
  </joint>
  <link
    name="left_arm_pitch_link">
    <inertial>
      <origin
        xyz="-0.00309185 0.0495522 0.00013831"
        rpy="0 0 0" />
      <mass
        value="0.48107005" />
      <inertia
        ixx="0.001385"
        ixy="-0.00009105"
        ixz="-0.00000128"
        iyy="0.00012361"
        iyz="-0.00000294"
        izz="0.00142017" />
    </inertial>
    <visual>
      <origin
        xyz="0 0 0"
        rpy="0 0 0" />
      <geometry>
        <mesh
          filename="../meshes/left_arm_pitch_link.STL" />
      </geometry>
      <material
        name="">
        <color
          rgba="0.796078431372549 0.823529411764706 0.937254901960784 1" />
      </material>
    </visual>
    <collision>
      <origin
        xyz="0 0.055 0"
        rpy="0 1.57 0" />
      <geometry>
         <cylinder radius="0.03" length="0.05"/>
      </geometry>
    </collision>
  </link>
  <joint
    name="left_arm_pitch_joint"
    type="revolute">
    <origin
      xyz="0 0.121749999999383 0.206175860782433"
      rpy="0 0 0" />
    <parent
      link="torso_link" />
    <child
      link="left_arm_pitch_link" />
    <axis
      xyz="0 1 0" />
    <limit
      lower="-1.57"
      upper="1.57"
      effort="18"
      velocity="3.7692" />
  </joint>
  <link
    name="left_arm_roll_link">
    <inertial>
      <origin
        xyz="-0.00460348 0 -0.02346753"
        rpy="0 0 0" />
      <mass
        value="0.10569114" />
      <inertia
        ixx="0.000117"
        ixy="0"
        ixz="-0.00003547"
        iyy="0.00013391"
        iyz="0"
        izz="0.00003756" />
    </inertial>
    <visual>
      <origin
        xyz="0 0 0"
        rpy="0 0 0" />
      <geometry>
        <mesh
          filename="../meshes/left_arm_roll_link.STL" />
      </geometry>
      <material
        name="">
        <color
          rgba="0.796078431372549 0.823529411764706 0.937254901960784 1" />
      </material>
    </visual>
    <collision>
      <origin
        xyz="-0.02 0 -0.12"
        rpy="0 0 0" />
      <geometry>
         <cylinder radius="0.03" length="0.10"/>
      </geometry>
    </collision>
  </link>
  <joint
    name="left_arm_roll_joint"
    type="revolute">
    <origin
      xyz="0.0200000000000018 0.056 0"
      rpy="0 0 0" />
    <parent
      link="left_arm_pitch_link" />
    <child
      link="left_arm_roll_link" />
    <axis
      xyz="1 0 0" />
    <limit
      lower="-0.25"
      upper="1"
      effort="18"
      velocity="3.7692" />
  </joint>
  <link
    name="left_arm_yaw_link">
    <inertial>
      <origin
        xyz=" -0.00007689 -0.00130242 -0.10578475"
        rpy="0 0 0" />
      <mass
        value="1.15030164" />
      <inertia
        ixx="0.01924211"
        ixy="-0.0000003"
        ixz="-0.00001105"
        iyy="0.01920722"
        iyz="-0.0002861"
        izz="0.00040341" />
    </inertial>
    <visual>
      <origin
        xyz="0 0 0"
        rpy="0 0 0" />
      <geometry>
        <mesh
          filename="../meshes/left_arm_yaw_link.STL" />
      </geometry>
      <material
        name="">
        <color
          rgba="0.796078431372549 0.823529411764706 0.937254901960784 1" />
      </material>
    </visual>
    <collision>
      <origin
        xyz="0 0 -0.19"
        rpy="0 1.57 1.57" />
      <geometry>
        <cylinder radius="0.03" length="0.05"/>
      </geometry>
    </collision>
  </link>
  <joint
    name="left_arm_yaw_joint"
    type="revolute">
    <origin
      xyz="-0.0200000000000002 0 -0.049999999999998"
      rpy="0 0 0" />
    <parent
      link="left_arm_roll_link" />
    <child
      link="left_arm_yaw_link" />
    <axis
      xyz="0 0 1" />
    <limit
      lower="-0.6"
      upper="1.3"
      effort="18"
      velocity="3.7692" />
  </joint>
  <link
    name="left_elbow_pitch_link">
    <inertial>
      <origin
        xyz="0.0241777072763705  -0.00451573 0.00015985"
        rpy="0 0 0" />
      <mass
        value="0.10324612" />
      <inertia
        ixx="0.00003728"
        ixy="-0.0000346"
        ixz="-0.00000071"
        iyy=" 0.00011225"
        iyz="-0.00000014"
        izz="0.00012911" />
    </inertial>
    <visual>
      <origin
        xyz="0 0 0"
        rpy="0 0 0" />
      <geometry>
        <mesh
          filename="../meshes/left_elbow_pitch_link.STL" />
      </geometry>
      <material
        name="">
        <color
          rgba="0.796078431372549 0.823529411764706 0.937254901960784 1" />
      </material>
    </visual>
    <collision>
      <origin
        xyz="0.10 -0.02 0"
        rpy="0 1.57 0" />
      <geometry>
          <cylinder radius="0.03" length="0.10"/>
      </geometry>
    </collision>
  </link>
  <joint
    name="left_elbow_pitch_joint"
    type="revolute">
    <origin
      xyz="0 0.0199999999999982 -0.188749999999997"
      rpy="0 0 0" />
    <parent
      link="left_arm_yaw_link" />
    <child
      link="left_elbow_pitch_link" />
    <axis
      xyz="0 1 0" />
    <limit
      lower="-0.6"
      upper="3.14"
      effort="18"
      velocity="3.7692" />
  </joint>
  <link
    name="left_elbow_yaw_link">
    <inertial>
      <origin
        xyz="0.05255763  -0.00004832 0.00003217"
        rpy="0 0 0" />
      <mass
        value="0.67956658" />
      <inertia
        ixx="0.00028087"
        ixy="-0.00000226"
        ixz="-0.00000062"
        iyy="0.0032603"
        iyz="-0.00000036"
        izz="0.00326171" />
    </inertial>
    <visual>
      <origin
        xyz="0 0 0"
        rpy="0 0 0" />
      <geometry>
        <mesh
          filename="../meshes/left_elbow_yaw_link.STL" />
      </geometry>
      <material
        name="">
        <color
          rgba="0.796078431372549 0.823529411764706 0.937254901960784 1" />
      </material>
    </visual>
    <!-- <collision>
      <origin
        xyz="0 0 0"
        rpy="0 0 0" />
      <geometry>
        <mesh
          filename="../meshes/left_elbow_yaw_link.STL" />
      </geometry>
    </collision> -->
  </link>
  <joint
    name="left_elbow_yaw_joint"
    type="revolute">
    <origin
      xyz="0.0499999999999968 -0.0199999999999994 0"
      rpy="0 0 0" />
    <parent
      link="left_elbow_pitch_link" />
    <child
      link="left_elbow_yaw_link" />
    <axis
      xyz="1 0 0" />
    <limit
      lower="-1.57"
      upper="1.57"
      effort="18"
      velocity="3.7692" />
  </joint>
  <link
    name="right_arm_pitch_link">
    <inertial>
      <origin
        xyz=" -0.00309185  -0.0495522 0.00013829"
        rpy="0 0 0" />
      <mass
        value="0.48107005" />
      <inertia
        ixx="0.001385"
        ixy="-0.00009105"
        ixz="-0.00000128"
        iyy="0.00012361"
        iyz="-0.00000296"
        izz="0.00142017" />
    </inertial>
    <visual>
      <origin
        xyz="0 0 0"
        rpy="0 0 0" />
      <geometry>
        <mesh
          filename="../meshes/right_arm_pitch_link.STL" />
      </geometry>
      <material
        name="">
        <color
          rgba="1 1 1 1" />
      </material>
    </visual>
    <collision>
      <origin
        xyz="0 -0.055 0"
        rpy="0 1.57 0" />
      <geometry>
         <cylinder radius="0.03" length="0.05"/>
      </geometry>
    </collision>
  </link>
  <joint
    name="right_arm_pitch_joint"
    type="revolute">
    <origin
      xyz="0 -0.121750000000346 0.206175860781721"
      rpy="0 0 0" />
    <parent
      link="torso_link" />
    <child
      link="right_arm_pitch_link" />
    <axis
      xyz="0 1 0" />
    <limit
      lower="-1.57"
      upper="1.57"
      effort="18"
      velocity="3.7692" />
  </joint>
  <link
    name="right_arm_roll_link">
    <inertial>
      <origin
        xyz="-0.00423887 -0.0003197 -0.02299932"
        rpy="0 0 0" />
      <mass
        value="0.10324612" />
      <inertia
        ixx="0.00011192"
        ixy="-0.00000066"
        ixz="-0.00003336"
        iyy="0.0001283"
        iyz="-0.00000143"
        izz="0.00003613" />
    </inertial>
    <visual>
      <origin
        xyz="0 0 0"
        rpy="0 0 0" />
      <geometry>
        <mesh
          filename="../meshes/right_arm_roll_link.STL" />
      </geometry>
      <material
        name="">
        <color
          rgba="0.796078431372549 0.823529411764706 0.937254901960784 1" />
      </material>
    </visual>
     <collision>
      <origin
        xyz="-0.02 0 -0.12"
        rpy="0 0 0" />
      <geometry>
         <cylinder radius="0.03" length="0.10"/>
      </geometry>
    </collision>
  </link>
  <joint
    name="right_arm_roll_joint"
    type="revolute">
    <origin
      xyz="0.0200000000000407 -0.056 0"
      rpy="0 0 0" />
    <parent
      link="right_arm_pitch_link" />
    <child
      link="right_arm_roll_link" />
    <axis
      xyz="1 0 0" />
    <limit
      lower="-1"
      upper="0.25"
      effort="18"
      velocity="3.7692" />
  </joint>
  <link
    name="right_arm_yaw_link">
    <inertial>
      <origin
        xyz="-0.00005647  0.00129475 -0.10587268"
        rpy="0 0 0" />
      <mass
        value="1.14935657" />
      <inertia
        ixx="0.01924257"
        ixy="-0.00000091"
        ixz="-0.00001007"
        iyy="0.01920615"
        iyz="-0.00028671"
        izz="0.00040282" />
    </inertial>
    <visual>
      <origin
        xyz="0 0 0"
        rpy="0 0 0" />
      <geometry>
        <mesh
          filename="../meshes/right_arm_yaw_link.STL" />
      </geometry>
      <material
        name="">
        <color
          rgba="0.796078431372549 0.823529411764706 0.937254901960784 1" />
      </material>
    </visual>
    <collision>
      <origin
        xyz="0 0 -0.19"
        rpy="0 1.57 1.57" />
      <geometry>
        <cylinder radius="0.03" length="0.05"/>
      </geometry>
    </collision>
  </link>
  <joint
    name="right_arm_yaw_joint"
    type="revolute">
    <origin
      xyz="-0.02 0 -0.0500000000000019"
      rpy="0 0 0" />
    <parent
      link="right_arm_roll_link" />
    <child
      link="right_arm_yaw_link" />
    <axis
      xyz="0 0 1" />
    <limit
      lower="-1.3"
      upper="0.6"
      effort="18"
      velocity="3.7692" />
  </joint>
  <link
    name="right_elbow_pitch_link">
    <inertial>
      <origin
        xyz="0.02346753  0.00460348 0"
        rpy="0 0 0" />
      <mass
        value="0.10569114" />
      <inertia
        ixx="0.00003756"
        ixy="-0.00003547"
        ixz="0"
        iyy="0.000117"
        iyz="0"
        izz="0.00013391" />
    </inertial>
    <visual>
      <origin
        xyz="0 0 0"
        rpy="0 0 0" />
      <geometry>
        <mesh
          filename="../meshes/right_elbow_pitch_link.STL" />
      </geometry>
      <material
        name="">
        <color
          rgba="0.796078431372549 0.823529411764706 0.937254901960784 1" />
      </material>
    </visual>
    <collision>
      <origin
        xyz="0.10 0.02 0"
        rpy="0 1.57 0" />
      <geometry>
          <cylinder radius="0.03" length="0.10"/>
      </geometry>
    </collision>
  </link>
  <joint
    name="right_elbow_pitch_joint"
    type="revolute">
    <origin
      xyz="0 -0.0200000000000019 -0.18875"
      rpy="0 0 0" />
    <parent
      link="right_arm_yaw_link" />
    <child
      link="right_elbow_pitch_link" />
    <axis
      xyz="0 1 0" />
    <limit
      lower="-0.6"
      upper="3.14"
      effort="18"
      velocity="3.7692" />
  </joint>
  <link
    name="right_elbow_yaw_link">
    <inertial>
      <origin
        xyz="0.05240866 0.00007821 0.00001993"
        rpy="0 0 0" />
      <mass
        value="0.68145673" />
      <inertia
        ixx="0.00028205"
        ixy="-0.00000224"
        ixz="-0.00000058"
        iyy="0.00326107"
        iyz="-0.00000061"
        izz=" 0.00326218" />
    </inertial>
    <visual>
      <origin
        xyz="0 0 0"
        rpy="0 0 0" />
      <geometry>
        <mesh
          filename="../meshes/right_elbow_yaw_link.STL" />
      </geometry>
      <material
        name="">
        <color
          rgba="1 1 1 1" />
      </material>
    </visual>
    <!-- <collision>
      <origin
        xyz="0 0 0"
        rpy="0 0 0" />
      <geometry>
        <mesh
          filename="../meshes/right_elbow_yaw_link.STL" />
      </geometry>
    </collision> -->
  </link>
  <joint
    name="right_elbow_yaw_joint"
    type="revolute">
    <origin
      xyz="0.0500000000000002 0.0200000000000004 0"
      rpy="0 0 0" />
    <parent
      link="right_elbow_pitch_link" />
    <child
      link="right_elbow_yaw_link" />
    <axis
      xyz="1 0 0" />
    <limit
      lower="-1.57"
      upper="1.57"
      effort="18"
      velocity="3.7692" />
  </joint>
</robot>